Workbook

Sheet README
A1: RMBS cash-flow valuation model — senior tranches, issuer-reported history
A3: Purpose
A4: Values a senior RMBS tranche from projected cash flows anchored on the last issuer-reported IPD, not on Bloomberg's factor/payment history.
A5: Collateral: quarterly step. Defaults (CDR), scheduled amortisation (level annuity, remaining term implied from the last reported scheduled principal), prepayments (CPR), recoveries after a lag.
A6: Liabilities: Class A vs aggregated subordinate notes; pro-rata / sequential switch on the prospectus tests; excess spread cures a Principal Deficiency Ledger (PDL); optional clean-up call; legal-final sweep.
A7: Pricing: price <-> discount margin (Newton on the projected index curve, ACT/360 simple per period), yield by XIRR, WAL, spread duration.
A9: Colour code
A10: Blue text = hard input · Yellow fill = key assumption / cell to fill · Black = formula · Green = link to another sheet.
A12: Workflow
A13: 1. Run rmbs_harvester.py (internet machine) -> out/<ISIN>.csv. Paste rows into 'History' (same column order).
A14: 2. In 'Deals', update the selected ISIN's row from the latest report (balances, margins, pool, WAC, scheduled principal, fixing).
A15: 3. In 'Inputs', pick the ISIN, set settlement (must fall before the next IPD), CPR/CDR/severity/lag, call mode, curve.
... A24: Model acceptance per ISIN: out/champion_models.csv (NO_RELIABLE_MODEL = price only under an explicit scenario).

Sheet Inputs
B1: RMBS senior tranche — cash-flow valuation
B3: Selected ISIN | C3: XS0222684655
B5: Deal data (linked from Deals) | F5: Scenario & pricing assumptions | J5: Valuation outputs
B6: Ticker | C6: =INDEX(Deals!$B$2:$B$18,MATCH($C$3,Deals!$A$2:$A$18,0)) -> MAGEL 3 A | F6: Settlement date | G6: 46289 | J6: Clean price | K6: =IF($G$7="DM",Engine!AO8/C11*100-G26/C11*100,G8) -> 98.5
B7: Last IPD | C7: =INDEX(Deals!$G$2:$G$18,MATCH($C$3,Deals!$A$2:$A$18,0)) -> 46251 | F7: Mode: PRICE (price→DM) or DM (DM→price) | G7: PRICE | J7: Accrued (per 100) | K7: =G26/C11*100 -> 0.26515556
B8: Next IPD (unadjusted) | C8: =INDEX(Deals!$H$2:$H$18,MATCH($C$3,Deals!$A$2:$A$18,0)) -> 46341 | F8: Clean price (per 100 current face) | G8: 98.5 | J8: Dirty price | K8: =K6+K7 -> 98.765156
B9: Legal final | C9: =INDEX(Deals!$I$2:$I$18,MATCH($C$3,Deals!$A$2:$A$18,0)) -> 57845 | F9: Input discount margin (bp) — used in DM mode | G9: 60 | J9: Discount margin (bp) | K9: =IF($G$7="DM",G9,Engine!BC9*10000) -> 59.498049
B10: A original (€) | C10: =INDEX(Deals!$J$2:$J$18,MATCH($C$3,Deals!$A$2:$A$18,0)) -> 1413750000 | F10: CPR (annual) | G10: 0.0424 | J10: Yield, annual effective (XIRR, ACT/365) | K10: =XIRR(Engine!BL10:BL190,Engine!BK10:BK190) -> 0.029180592
B11: A current (€) | C11: =INDEX(Deals!$K$2:$K$18,MATCH($C$3,Deals!$A$2:$A$18,0)) -> 1.1084507e+08 | F11: CDR (annual) | G11: 0.001 | J11: Yield, quarterly compounded | K11: =4*((1+K10)^0.25-1) -> 0.028866606
B12: Subordinate current (€) | C12: =INDEX(Deals!$L$2:$L$18,MATCH($C$3,Deals!$A$2:$A$18,0)) -> 8507872.5 | F12: Loss severity | G12: 0.2 | J12: WAL (years, ACT/365) | K12: =SUMPRODUCT(Engine!AD11:AD190,Engine!AJ11:AJ190)/SUM(Engine!AD11:AD190) -> 4.8676881
B13: A margin | C13: =INDEX(Deals!$M$2:$M$18,MATCH($C$3,Deals!$A$2:$A$18,0)) -> 0.0026 | F13: Recovery lag (quarters) | G13: 8 | J13: Spread duration (±10bp DM) | K13: =(Engine!BG8-Engine!BI8)/(2*G27*0.001) -> 4.4801644
B14: Sub WA margin | C14: =INDEX(Deals!$N$2:$N$18,MATCH($C$3,Deals!$A$2:$A$18,0)) -> 0.0070626087 | F14: 90d+ arrears ratio for pro-rata test | G14: =C29 -> 5.3028846e-05 | J14: Time to next reset (years) | K14: =(Engine!C11-G6)/365 -> 0.14520548
B15: Current-period index fixing | C15: =INDEX(Deals!$O$2:$O$18,MATCH($C$3,Deals!$A$2:$A$18,0)) -> 0.02252 | F15: Call mode: 0 none · 1 first eligible IPD · 2 on/after date | G15: 0 | J15: Last principal date | K15: =SUMPRODUCT(MAX((Engine!AD11:AD190>0.005)*Engine!C11:C190)) -> 50175
B16: Pool current, net (€) | C16: =INDEX(Deals!$P$2:$P$18,MATCH($C$3,Deals!$A$2:$A$18,0)) -> 1.1935638e+08 | F16: Call date (mode 2) | G16: 46433 | J16: Projected principal loss, Class A (€) | K16: =SUMPRODUCT((Engine!E11:E190=TRUE())*(Engine!O11:O190-Engine!AD11:AD190)) -> 0
B17: Pool at cut-off (€) | C17: =INDEX(Deals!$Q$2:$Q$18,MATCH($C$3,Deals!$A$2:$A$18,0)) -> 1.5e+09 | F17: Flat EUR 3M forward (if no curve) | G17: 0.02252 | J17: Call date used | K17: =IFERROR(INDEX(Engine!C11:C190,MATCH(TRUE(),Engine!AB11:AB190,0)),"no call") -> no call
B18: WAC | C18: =INDEX(Deals!$R$2:$R$18,MATCH($C$3,Deals!$A$2:$A$18,0)) -> 0.03174 | F18: Use Curve sheet (1/0) | G18: 0 | J18: DM solver residual (€) | K18: =IF($G$7="DM",0,Engine!BC8-G27) -> 0
B19: Pool ref. for sched. (€) | C19: =INDEX(Deals!$S$2:$S$18,MATCH($C$3,Deals!$A$2:$A$18,0)) -> 1.2339789e+08 | F19: Class A coupon floor (blank = none) | G19: 0 | J19: Freshness check | K19: =IF(G6>=Engine!C11,"STALE: settlement on/after next IPD — harvest the newer report",IF(G6<C7,"ERROR: settlement before last IPD","OK")) -> OK
B20: Observed sched. principal (€/qtr) | C20: =INDEX(Deals!$T$2:$T$18,MATCH($C$3,Deals!$A$2:$A$18,0)) -> 2257065.1 | F20: Class A principal paid / due (1 = no shortfall; Hipocat 11 option) | G20: 1 | J20: Class A principal conservation (should be 0) | K20: =C11-SUM(Engine!AD11:AD190)-K16 -> 0
B21: Pro-rata allowed (1/0) | C21: =INDEX(Deals!$W$2:$W$18,MATCH($C$3,Deals!$A$2:$A$18,0)) -> 1 | F21: Quarterly prepay rate 1-(1-CPR)^0.25 | G21: =1-(1-G10)^0.25 -> 0.010772834 | J21: Class A total cash flow (€) | K21: =SUM(Engine!AI11:AI190) -> 1.2488095e+08
B22: Pro-rata: A/A_orig <= | C22: =INDEX(Deals!$X$2:$X$18,MATCH($C$3,Deals!$A$2:$A$18,0)) -> 0.75 | F22: Quarterly default rate 1-(1-CDR)^0.25 | G22: =1-(1-G11)^0.25 -> 0.0002500938 | J22: Projected A factor in 1y | K22: =INDEX(Engine!AG11:AG190,4)/C10 -> 0.069451934
B23: Pro-rata: arrears < | C23: =INDEX(Deals!$Y$2:$Y$18,MATCH($C$3,Deals!$A$2:$A$18,0)) -> 0.018 | F23: Quarterly WAC | G23: =C18/4 -> 0.007935
B24: Clean-up call threshold | C24: =INDEX(Deals!$Z$2:$Z$18,MATCH($C$3,Deals!$A$2:$A$18,0)) -> 0.1 | F24: Implied remaining term (quarters) | G24: =IFERROR(LN(1+G23*C19/C20)/LN(1+G23),0) -> 45.59177 | J24: Legend: blue = input, yellow = assumption to set, green = link to Deals, black = formula.
B25: Fees fixed (€/qtr) | C25: =INDEX(Deals!$AA$2:$AA$18,MATCH($C$3,Deals!$A$2:$A$18,0)) -> 100000 | F25: Implied remaining term (years) | G25: =G24/4 -> 11.397943
B26: Fees (bp p.a.) | C26: =INDEX(Deals!$AB$2:$AB$18,MATCH($C$3,Deals!$A$2:$A$18,0)) -> 0.001 | F26: Accrued (€) | G26: =C11*(C15+C13)*(G6-C7)/360 -> 293911.86
B27: Reported CPR last qtr | C27: =INDEX(Deals!$U$2:$U$18,MATCH($C$3,Deals!$A$2:$A$18,0)) -> 0.0424 | F27: Dirty amount target (€) | G27: =K6/100*C11+G26 -> 1.094763e+08
B28: Data status | C28: =INDEX(Deals!$AC$2:$AC$18,MATCH($C$3,Deals!$A$2:$A$18,0)) -> History 23 IPDs to 2026-08-17; gate INCOMPLETE; model NO_RELIABLE_MODEL; CONFIG_INCOMPLETE: fees,swap
B29: 90d+ arrears ratio (reported) | C29: =INDEX(Deals!$V$2:$V$18,MATCH($C$3,Deals!$A$2:$A$18,0)) -> 5.3028846e-05
F36: History calibration (selected ISIN)
F37: IPDs in History | G37: =COUNTIF(History!A4:A2003,$C$3) -> 23
F38: Latest IPD in History | G38: =_xlfn.MAXIFS(History!E4:E2003,History!A4:A2003,$C$3) -> 46251
F39: Mean realised CPR (prepay only), last 12m | G39: =IFERROR(AVERAGEIFS(History!BC4:BC2003,History!A4:A2003,$C$3,History!E4:E2003,">"&EDATE(G38,-12)),"n/a") -> 0.048467283
F40: Rows not 'ok' after validation (count) | G40: =SUMPRODUCT((History!A4:A2003=$C$3)*(LEFT(History!AR4:AR2003,6)="review")) -> 0
F41: Last IPD in History = Deals last IPD? | G41: =IF(G38=C7,"consistent","CHECK: Deals row older/newer than History") -> consistent

Sheet Deals
A1: ISIN | B1: Ticker | C1: Deal | D1: Country | E1: Reporting entity | F1: As-of IPD (last report) | G1: Last IPD | H1: Next IPD (unadj.) | I1: Legal final | J1: A original (€) | K1: A current (€) | L1: Subordinate current (€) | M1: A margin | N1: Sub WA margin | O1: Current-period index fixing | P1: Pool current, net of deemed losses (€) | Q1: Pool at cut-off (€) | R1: WAC | S1: Pool ref. for sched. amort. (€) | T1: Observed sched. principal last qtr (€) | U1: Reported CPR last qtr | V1: 90-365d arrears ratio | W1: Pro-rata allowed (1/0) | X1: Pro-rata: A/A_orig <= | Y1: Pro-rata: arrears < | Z1: Clean-up call (% of cut-off pool) | AA1: Fees fixed (€/qtr) | AB1: Fees (bp p.a. of pool) | AC1: Data status | AD1: IPD rule | AE1: Margin step-ups | AF1: Coupon floor | AG1: Amortisation / triggers | AH1: Reserve | AI1: Issuer-stated call | AJ1: Principal shortfall option | AK1: Conflicts / unverified
A2: XS0222684655 | B2: MAGEL 3 A | C2: Magellan Mortgages No. 3 plc | D2: PT | E2: BCP | F2: 46251 | G2: 46251 | H2: 46341 | I2: 57845 | J2: 1413750000 | K2: 1.1084507e+08 | L2: 8507872.5 | M2: 0.0026 | N2: 0.0070626087 | O2: 0.02252 | P2: 1.1935638e+08 | Q2: 1.5e+09 | R2: 0.03174 | S2: 1.2339789e+08 | T2: 2257065.1 | U2: 0.0424 | V2: 5.3028846e-05 | W2: 1 | X2: 0.75 | Y2: 0.018 | Z2: 0.1 | AA2: 100000 | AB2: 0.001 | AC2: History 23 IPDs to 2026-08-17; gate INCOMPLETE; model NO_RELIABLE_MODEL; CONFIG_INCOMPLETE: fees,swap | AD2: {"months": [2, 5, 8, 11], "day": 15, "convention": "following", "calendar": "PT"} | AE2: 2012-08-15: 26bp | AF2: 0.0 from 2018-01-01 | AG2: {"amortisation": {"mode": "pro_rata_if_test_pass", "switch_to_sequential_if": ["Pro-Rata Test FAIL (report Sec.3)"]}, "triggers": {"prorata_A_over_A_orig_max": null, "arrears_90_365_ratio_max": null, "note": "test result is read from each report (Pro | AH2: {"observed": [{"date": "2009-02-16", "balance": 13500000}, {"date": "2026-08-17", "balance": 9000000}], "required_rule": null} | AJ2: no | AK2: legal_final day (Notes due 2058 per Euronext RIS; day from original model); coupon_floor_from: Aug-2017 coupon -0.069%, Nov-2017 not read; swap; fees
A3: XS0260784318 | B3: MAGEL 4 A | C3: Magellan Mortgages No. 4 plc | D3: PT | E3: BCP | F3: 46223 | G3: 46223 | H3: 46315 | I3: 58276 | J3: 1413750000 | K3: 1.3524357e+08 | L3: 10646700 | M3: 0.0028 | N3: 0.0069652174 | O3: 0.02238 | P3: 1.4588906e+08 | Q3: 1.5e+09 | R3: 0.02996 | S3: 1.5030128e+08 | T3: 2411455.1 | U3: 0.0522 | V3: 5.6418726e-05 | W3: 1 | X3: 0.75 | Y3: 0.018 | Z3: 0.1 | AA3: 40000 | AB3: 0.001 | AC3: History 10 IPDs to 2026-07-20; gate INCOMPLETE; model NO_RELIABLE_MODEL (THIN_HISTORY); CONFIG_INCOMPLETE: fees,swap | AD3: {"months": [1, 4, 7, 10], "day": 20, "convention": "following", "calendar": "PT"} | AE3: 2017-04-20: 28bp | AF3: 0.0 from 2017-04-20 | AG3: {"amortisation": {"mode": "pro_rata_if_test_pass", "note": "pro-rata since Jul-2008 (Moody's Feb-2021)"}, "triggers": {"note": "Pro-Rata Test read from each report; thresholds not transcribed"}} | AH3: {"observed": [{"date": "2021-02-01", "balance": 9000000, "note": "at floor (Moody's)"}], "required_rule": null} | AJ3: no | AK3: margin step-up IPD (bounded, see margin_steps); coupon_floor_from: first floored IPD observed is Apr-2017 (earlier reports not read); clean_up_call_pct (from original model, prospectus not read); legal_final day; swap; fees
A4: XS0230694233 | B4: LUSI 4 A | C4: Lusitano Mortgages No. 4 plc | D4: PT | E4: Citibank N.A. / novobanco | J4: 1134000000 | AC4: History 0 IPDs; gate MANUAL_REQUIRED; model MANUAL_REQUIRED; CONFIG_INCOMPLETE: amortisation,clean_up_call_pct,coupon_floor,denomination,fees,ipd_rule,legal_final,notes,reserve,swap,triggers | AD4: null | AE4: none known | AG4: {"amortisation": null, "triggers": null} | AH4: null | AJ4: no | AK4: legal final: ESFG 'December 2048' vs oblible 14-Sep-2048
A5: XS0268642161 | B5: LUSI 5 A | C5: Lusitano Mortgages No. 5 plc | D5: PT | E5: Citibank N.A. / novobanco | I5: 58271 | AC5: History 0 IPDs; gate MANUAL_REQUIRED; model MANUAL_REQUIRED; CONFIG_INCOMPLETE: amortisation,clean_up_call_pct,coupon_floor,denomination,fees,ipd_rule,margin_bp,notes,original_balance,reserve,swap,triggers | AD5: null | AE5: none known | AG5: {"amortisation": null, "triggers": null} | AH5: null | AJ5: no
A6: XS0312981649 | B6: LUSI 6 A | C6: Lusitano Mortgages No. 6 plc | D6: PT | E6: Citibank N.A. / novobanco | AC6: History 0 IPDs; gate MANUAL_REQUIRED; model MANUAL_REQUIRED; CONFIG_INCOMPLETE: amortisation,clean_up_call_pct,coupon_floor,denomination,fees,ipd_rule,legal_final,margin_bp,notes,original_balance,reserve,swap,triggers | AD6: null | AE6: none known | AG6: {"amortisation": null, "triggers": null} | AH6: null | AJ6: no
A7: ES0377992005 | B7: TDAC 5 A | C7: TDA CAM 5, FTA | D7: ES | E7: Titulizacion de Activos SGFT | F7: 44860 | G7: 44860 | H7: 44952 | I7: 52530 | J7: 1944000000 | K7: 210064000 | M7: 0.0012 | Z7: 0.1 | AC7: History 8 IPDs to 2022-10-26; gate INCOMPLETE; model NO_RELIABLE_MODEL (THIN_HISTORY); CONFIG_INCOMPLETE: fees,swap; pool/WAC/sched. principal not in the filings held | AD7: {"months": [1, 4, 7, 10], "day": 26, "convention": "following", "calendar": "TARGET"} | AE7: none known | AF7: 0.0 from 2016-01-01 to 2022-04-30 | AG7: {"amortisation": {"mode": "sequential", "note": "A then B"}, "triggers": {"note": "sequential; no pro-rata"}} | AH7: {"note": "non-amortising reserve fund (Moody's)"} | AJ7: no | AK7: fees; swap; first_ipd; reserve size
A8: ES0377993029 | B8: TDAC 6 A3 | C8: TDA CAM 6, FTA | D8: ES | E8: Titulizacion de Activos SGFT | I8: 52715 | AC8: History 0 IPDs; gate NO_HISTORY; model NO_RELIABLE_MODEL; CONFIG_INCOMPLETE: clean_up_call_pct,coupon_floor,fees,margin_bp,notes,original_balance,reserve,swap,triggers | AD8: {"months": [1, 4, 7, 10], "day": 28, "convention": "following", "calendar": "TARGET", "inferred": "from legal final 28-Apr-2044"} | AE8: none known | AG8: {"amortisation": {"mode": "sequential", "note": "Moody's: sequential, non-amortising reserve; Fitch: sequential once pool < 10%"}, "triggers": null} | AH8: null | AJ8: no | AK8: amortisation: Moody's sequential vs Fitch pro-rata until pool < 10%; ipd_rule (inferred from legal final date); denomination
A9: ES0377994019 | B9: TDAC 7 A2 | C9: TDA CAM 7, FTA | D9: ES | E9: Titulizacion de Activos SGFT | I9: 54480 | AC9: History 0 IPDs; gate NO_HISTORY; model NO_RELIABLE_MODEL; CONFIG_INCOMPLETE: clean_up_call_pct,coupon_floor,fees,margin_bp,notes,original_balance,reserve,swap,triggers | AD9: {"months": [2, 5, 8, 11], "day": 26, "convention": "following", "calendar": "TARGET", "inferred": "from legal final 26-Feb-2049"} | AE9: none known | AG9: {"amortisation": {"mode": "sequential", "note": "A1/A2/A3 order per prospectus not yet read; Moody's: sequential"}, "triggers": null} | AH9: null | AJ9: no | AK9: ipd_rule (inferred); denomination; A2/A3 sequencing
A10: ES0377994027 | B10: TDAC 7 A3 | C10: TDA CAM 7, FTA | D10: ES | E10: Titulizacion de Activos SGFT | I10: 54480 | AC10: History 0 IPDs; gate NO_HISTORY; model NO_RELIABLE_MODEL; CONFIG_INCOMPLETE: clean_up_call_pct,coupon_floor,fees,margin_bp,notes,original_balance,reserve,swap,triggers | AD10: {"months": [2, 5, 8, 11], "day": 26, "convention": "following", "calendar": "TARGET", "inferred": "from legal final 26-Feb-2049"} | AE10: none known | AG10: {"amortisation": {"mode": "sequential", "note": "A1/A2/A3 order per prospectus not yet read; Moody's: sequential"}, "triggers": null} | AH10: null | AJ10: no | AK10: ipd_rule (inferred); denomination; A2/A3 sequencing
A11: ES0377966009 | B11: TDAC 8 A | C11: TDA CAM 8, FTA | D11: ES | E11: Titulizacion de Activos SGFT | F11: 44161 | G11: 44161 | H11: 44253 | I11: 54480 | J11: 1635400000 | AC11: History 2 IPDs to 2020-11-26; gate NO_HISTORY; model NO_RELIABLE_MODEL; CONFIG_INCOMPLETE: clean_up_call_pct,coupon_floor,fees,margin_bp,swap,triggers; pool/WAC/sched. principal not in the filings held | AD11: {"months": [2, 5, 8, 11], "day": 26, "convention": "following", "calendar": "TARGET"} | AE11: none known | AG11: {"amortisation": {"mode": "pro_rata_while_pool_factor_ge", "threshold": 0.1, "note": "now irreversibly sequential (Fitch Dec-2025)"}, "triggers": null} | AH11: {"observed": [{"date": "2020-11-26", "balance": 8500000}], "note": "at floor (Fitch Dec-2025)"} | AJ11: no | AK11: margin
A12: ES0377955010 | B12: TDAC 9 A2 | C12: TDA CAM 9, FTA | D12: ES | E12: Titulizacion de Activos SGFT | I12: 54906 | AC12: History 0 IPDs; gate NO_HISTORY; model NO_RELIABLE_MODEL; CONFIG_INCOMPLETE: clean_up_call_pct,coupon_floor,fees,margin_bp,notes,original_balance,triggers | AD12: {"months": [1, 4, 7, 10], "day": 28, "convention": "following", "calendar": "TARGET", "inferred": "from legal final 28-Apr-2050"} | AE12: none known | AG12: {"amortisation": {"mode": "sequential", "note": "B/C/D interest-deferral triggers breached (Fitch Dec-2025)"}, "triggers": null} | AH12: {"note": "at floor since Oct-2025"} | AJ12: no | AK12: ipd_rule (inferred); closing day
A13: ES0359091016 | B13: CAJAM 2006-1 A2 | C13: MADRID RMBS I, FTA | D13: ES | E13: Titulizacion de Activos SGFT | I13: 54596 | AC13: History 0 IPDs; gate NO_HISTORY; model NO_RELIABLE_MODEL; CONFIG_INCOMPLETE: clean_up_call_pct,coupon_floor,fees,margin_bp,notes,original_balance,swap,triggers | AD13: {"months": [3, 6, 9, 12], "day": 22, "convention": "following", "calendar": "TARGET", "inferred": "from legal final 22-Jun-2049"} | AE13: none known | AG13: {"amortisation": {"mode": "sequential", "note": "pro-rata condition not met (S&P 2022)"}, "triggers": null} | AH13: {"note": "fully depleted Mar-2013..Apr-2019; ~11% of target in 2022 (S&P)"} | AJ13: no | AK13: ipd_rule (inferred); margin (only AAA weighted 13.44bp seen)
A14: ES0380957003 | B14: UCI 15 A | C14: F.T.A. U.C.I. 15 | D14: ES | E14: Santander de Titulizacion SGFT | F14: 46191 | G14: 46191 | H14: 46283 | I14: 53314 | J14: 1340600000 | K14: 81800463 | L14: 1.0084e+08 | M14: 0.0014 | N14: 0.004508449 | O14: 0.02408 | P14: 180964103 | Q14: 1.43e+09 | R14: 0.0326 | S14: 1.87982e+08 | T14: 3481000 | U14: 0.0745 | V14: 0.089946168 | W14: 1 | X14: 1 | Y14: 0.02 | Z14: 0.1 | AA14: 36500 | AB14: 0 | AC14: History 3 IPDs to 2026-06-18; gate INCOMPLETE; model NO_RELIABLE_MODEL; CONFIG_INCOMPLETE: coupon_floor,fees,swap | AD14: {"months": [3, 6, 9, 12], "day": 18, "convention": "following", "calendar": "TARGET"} | AE14: none known | AG14: {"amortisation": {"mode": "pro_rata_unless_trigger", "note": "90d+ arrears trigger reached -> B and C not amortised"}, "triggers": {"arrears_90d_ratio_max": 0.02, "observed_2026_06": 0.0899}} | AH14: {"observed": [{"date": "2026-06-18", "balance": 11440000}]} | AI14: 2027-12-20 | AJ14: no | AK14: legal final: santandermedia asset 18-Dec-2045 vs original workbook 18-Dec-2048
A15: ES0338186010 | B15: UCI 16 A2 | C15: F.T.A. U.C.I. 16 | D15: ES | E15: Santander de Titulizacion SGFT | AC15: History 0 IPDs; gate NO_HISTORY; model NO_RELIABLE_MODEL; CONFIG_INCOMPLETE: amortisation,clean_up_call_pct,coupon_floor,denomination,fees,ipd_rule,legal_final,margin_bp,notes,original_balance,reserve,swap,triggers | AD15: null | AE15: none known | AG15: {"amortisation": null, "triggers": null} | AH15: null | AJ15: no | AK15: IPD 16-Sep-2026 announced on BME (HANDOFF) - months not confirmed
A16: ES0345672010 | B16: HIPO 11 A2 | C16: HIPOCAT 11, FTA | D16: ES | E16: Europea de Titulizacion | F16: 43753 | G16: 43753 | H16: 43845 | I16: 54803 | J16: 1083200000 | K16: 217021000 | M16: 0.0013 | Q16: 1.6e+09 | Z16: 0.1 | AC16: History 16 IPDs to 2019-10-15; gate INCOMPLETE; model NO_RELIABLE_MODEL; CONFIG_INCOMPLETE: coupon_floor,fees,swap; pool/WAC/sched. principal not in the filings held | AD16: {"months": [1, 4, 7, 10], "day": 15, "convention": "following", "calendar": "TARGET"} | AE16: none known | AG16: {"amortisation": {"mode": "pro_rata_if_conditions", "note": "A1/A2/A3 split by date-dependent rule; conditions in accounts trigger annex (reserve at required, arrears<1%, pool>10%, C>=8%)"}, "triggers": {"arrears_3m_ratio_max": 0.01, "pool_factor_min | AH16: {"required": 28000000, "observed": [{"date": "2016-12-31", "note": "Fondo de Reserva dotado 40.87 (EUR) vs requerido 28,000,000"}]} | AJ16: YES (set Inputs!G20 = paid/due) | AK16: printed IPDs 2015-16 fall on the 21st-23rd, 2018-19 on the 15th (see calendar_checks)
A17: ES0345721015 | B17: HIPO 9 A2a | C17: HIPOCAT 9, FTA | D17: ES | E17: Europea de Titulizacion | J17: 500000000 | AC17: History 0 IPDs; gate NO_HISTORY; model NO_RELIABLE_MODEL; CONFIG_INCOMPLETE: amortisation,clean_up_call_pct,coupon_floor,fees,legal_final,reserve,swap,triggers | AD17: {"months": [1, 4, 7, 10], "day": 15, "convention": "following", "calendar": "TARGET"} | AE17: none known | AG17: {"amortisation": null, "triggers": null} | AH17: null | AJ17: no | AK17: notes (inferred: original / 100,000)
A18: ES0345721023 | B18: HIPO 9 A2b | C18: HIPOCAT 9, FTA | D18: ES | E18: Europea de Titulizacion | J18: 236200000 | AC18: History 0 IPDs; gate NO_HISTORY; model NO_RELIABLE_MODEL; CONFIG_INCOMPLETE: amortisation,clean_up_call_pct,coupon_floor,fees,legal_final,reserve,swap,triggers | AD18: {"months": [1, 4, 7, 10], "day": 15, "convention": "following", "calendar": "TARGET"} | AE18: none known | AG18: {"amortisation": null, "triggers": null} | AH18: null | AJ18: no | AK18: notes (inferred: original / 100,000)

Sheet Curve
A1: EUR 3M forward curve by IPD (paste forwards in column C, decimal; e.g. from Bloomberg FWCV / S0045 forward rates)
A3: k | B3: IPD date | C3: Forward 3M (paste) | D3: Rate used
A4: 1 | B4: =Engine!C11 -> 46342 | D4: =IF(AND(Inputs!$G$18=1,C4<>""),C4,Inputs!$G$17) -> 0.02252
A5: 2 | B5: =Engine!C12 -> 46433 | D5: =IF(AND(Inputs!$G$18=1,C5<>""),C5,Inputs!$G$17) -> 0.02252
A6: 3 | B6: =Engine!C13 -> 46524 | D6: =IF(AND(Inputs!$G$18=1,C6<>""),C6,Inputs!$G$17) -> 0.02252
A7: 4 | B7: =Engine!C14 -> 46615 | D7: =IF(AND(Inputs!$G$18=1,C7<>""),C7,Inputs!$G$17) -> 0.02252
A8: 5 | B8: =Engine!C15 -> 46706 | D8: =IF(AND(Inputs!$G$18=1,C8<>""),C8,Inputs!$G$17) -> 0.02252
A9: 6 | B9: =Engine!C16 -> 46798 | D9: =IF(AND(Inputs!$G$18=1,C9<>""),C9,Inputs!$G$17) -> 0.02252
A10: 7 | B10: =Engine!C17 -> 46888 | D10: =IF(AND(Inputs!$G$18=1,C10<>""),C10,Inputs!$G$17) -> 0.02252
A11: 8 | B11: =Engine!C18 -> 46980 | D11: =IF(AND(Inputs!$G$18=1,C11<>""),C11,Inputs!$G$17) -> 0.02252
A12: 9 | B12: =Engine!C19 -> 47072 | D12: =IF(AND(Inputs!$G$18=1,C12<>""),C12,Inputs!$G$17) -> 0.02252
A13: 10 | B13: =Engine!C20 -> 47164 | D13: =IF(AND(Inputs!$G$18=1,C13<>""),C13,Inputs!$G$17) -> 0.02252
A14: 11 | B14: =Engine!C21 -> 47253 | D14: =IF(AND(Inputs!$G$18=1,C14<>""),C14,Inputs!$G$17) -> 0.02252
A15: 12 | B15: =Engine!C22 -> 47345 | D15: =IF(AND(Inputs!$G$18=1,C15<>""),C15,Inputs!$G$17) -> 0.02252
... A183: 180 | B183: =Engine!C190 -> 62687 | D183: =IF(AND(Inputs!$G$18=1,C183<>""),C183,Inputs!$G$17) -> 0.02252

Sheet Engine
A1: Projection engine — quarterly IPD step (row 10 = state after last reported IPD)
AN6: Newton on DM: row 7 = DM tried, row 8 = PV(€) = Σ CF·Π 1/(1+(index+DM)τ'), row 9 = next DM | AO6: iter 0 | AQ6: iter 1 | AS6: iter 2 | AU6: iter 3 | AW6: iter 4 | AY6: iter 5 | BA6: iter 6 | BC6: final | BG6: DM -10bp | BI6: DM +10bp
AO7: =IF(Inputs!$G$7="DM",Inputs!$G$9/10000,Inputs!$C$13) -> 0.0026 | AP7: =AO7+0.0001 -> 0.0027 | AQ7: =AO9 -> 0.0059134629 | AR7: =AQ7+0.0001 -> 0.0060134629 | AS7: =AQ9 -> 0.0059498126 | AT7: =AS7+0.0001 -> 0.0060498126 | AU7: =AS9 -> 0.0059498049 | AV7: =AU7+0.0001 -> 0.0060498049 | AW7: =AU9 -> 0.0059498049 | AX7: =AW7+0.0001 -> 0.0060498049 | AY7: =AW9 -> 0.0059498049 | AZ7: =AY7+0.0001 -> 0.0060498049 | BA7: =AY9 -> 0.0059498049 | BB7: =BA7+0.0001 -> 0.0060498049 | BC7: =BA9 -> 0.0059498049 | BD7: =BC7+0.0001 -> 0.0060498049 | BG7: =IF(Inputs!$G$7="DM",Inputs!$G$9/10000,BC9)-0.001 -> 0.0049498049 | BI7: =IF(Inputs!$G$7="DM",Inputs!$G$9/10000,BC9)+0.001 -> 0.0069498049
AO8: =SUMPRODUCT($AI$11:$AI$190,EXP(-AO11:AO190)) -> 1.111379e+08 | AP8: =SUMPRODUCT($AI$11:$AI$190,EXP(-AP11:AP190)) -> 1.1108775e+08 | AQ8: =SUMPRODUCT($AI$11:$AI$190,EXP(-AQ11:AQ190)) -> 1.0949413e+08 | AR8: =SUMPRODUCT($AI$11:$AI$190,EXP(-AR11:AR190)) -> 1.0944509e+08 | AS8: =SUMPRODUCT($AI$11:$AI$190,EXP(-AS11:AS190)) -> 1.094763e+08 | AT8: =SUMPRODUCT($AI$11:$AI$190,EXP(-AT11:AT190)) -> 1.0942727e+08 | AU8: =SUMPRODUCT($AI$11:$AI$190,EXP(-AU11:AU190)) -> 1.094763e+08 | AV8: =SUMPRODUCT($AI$11:$AI$190,EXP(-AV11:AV190)) -> 1.0942727e+08 | ... BD8: =SUMPRODUCT($AI$11:$AI$190,EXP(-BD11:BD190)) -> 1.0942727e+08 | BG8: =SUMPRODUCT($AI$11:$AI$190,EXP(-BG11:BG190)) -> 1.0996842e+08 | BI8: =SUMPRODUCT($AI$11:$AI$190,EXP(-BI11:BI190)) -> 1.0898748e+08
A9: k | B9: IPD unadj. | C9: IPD | D9: Live | E9: Last live | F9: τ (ACT/360) | G9: Index | H9: Pool beg. | I9: Defaults | J9: n remaining | K9: Scheduled | L9: Prepay | M9: Recoveries | N9: Interest coll. | O9: A beg. | P9: Sub beg. | Q9: Fees | R9: Int. A | S9: Int. Sub | T9: Excess spread | U9: PDL open | V9: PDL cure | W9: PDL close | X9: Principal avail. | Y9: Pro-rata test | Z9: Call cond. | AA9: Called | AB9: Call IPD | AC9: A share | AD9: Prin. A | AE9: Prin. Sub | AF9: Pool end | AG9: A end | AH9: Sub end | AI9: CF A | AJ9: t (yrs) | AK9: A factor end | AM9: τ' settle-adj. | AO9: =IFERROR(AO7-(AO8-Inputs!$G$27)*0.0001/(AP8-AO8),AO7) -> 0.0059134629 | AQ9: =IFERROR(AQ7-(AQ8-Inputs!$G$27)*0.0001/(AR8-AQ8),AQ7) -> 0.0059498126 | AS9: =IFERROR(AS7-(AS8-Inputs!$G$27)*0.0001/(AT8-AS8),AS7) -> 0.0059498049 | AU9: =IFERROR(AU7-(AU8-Inputs!$G$27)*0.0001/(AV8-AU8),AU7) -> 0.0059498049 | AW9: =IFERROR(AW7-(AW8-Inputs!$G$27)*0.0001/(AX8-AW8),AW7) -> 0.0059498049 | AY9: =IFERROR(AY7-(AY8-Inputs!$G$27)*0.0001/(AZ8-AY8),AY7) -> 0.0059498049 | BA9: =IFERROR(BA7-(BA8-Inputs!$G$27)*0.0001/(BB8-BA8),BA7) -> 0.0059498049 | BC9: =IFERROR(BC7-(BC8-Inputs!$G$27)*0.0001/(BD8-BC8),BC7) -> 0.0059498049 | BE9: Prin. A due | BF9: A shortfall c/f | BK9: XIRR date | BL9: XIRR cash
C10: =Inputs!$C$7 -> 46251 | D10: =TRUE() -> TRUE | W10: 0 | AA10: =FALSE() -> FALSE | AF10: =Inputs!$C$16 -> 1.1935638e+08 | AG10: =Inputs!$C$11 -> 1.1084507e+08 | AH10: =Inputs!$C$12 -> 8507872.5 | BF10: 0 | BK10: =Inputs!$G$6 -> 46289 | BL10: =-Inputs!$K$8/100*Inputs!$C$11 -> -1.094763e+08
A11: 1 | B11: =EDATE(Inputs!$C$8,3*(A11-1)) -> 46341 | C11: =WORKDAY(B11-1,1) -> 46342 | D11: =C11<=Inputs!$C$9 -> TRUE | E11: =AND(D11,NOT(D12)) -> FALSE | F11: =(C11-C10)/360 -> 0.25277778 | G11: =Inputs!$C$15 -> 0.02252 | H11: =AF10 -> 1.1935638e+08 | I11: =IF(D11,H11*Inputs!$G$22,0) -> 29850.291 | J11: =MAX(Inputs!$G$24-(A11-1),1) -> 45.59177 | K11: =IF(D11,MIN(H11-I11,IF(J11>1,(H11-I11)*Inputs!$G$23/((1+Inputs!$G$23)^J11-1),H11-I11)),0) -> 2182596 | L11: =IF(D11,(H11-I11-K11)*Inputs!$G$21,0) -> 1261972.2 | M11: =IF(A11>Inputs!$G$13,(1-Inputs!$G$12)*INDEX($I$11:$I$190,A11-Inputs!$G$13),0) -> 0 | N11: =IF(D11,(H11-I11)*Inputs!$G$23,0) -> 946856.01 | O11: =AG10 -> 1.1084507e+08 | P11: =AH10 -> 8507872.5 | Q11: =IF(AND(D11,O11+P11>0),Inputs!$C$25+Inputs!$C$26*H11/4,0) -> 129839.09 | R11: =O11*IF(Inputs!$G$19="",G11+Inputs!$C$13,MAX(Inputs!$G$19,G11+Inputs!$C$13))*F11 -> 703841.55 | S11: =P11*(G11+Inputs!$C$14)*F11 -> 63620.391 | T11: =N11+M11-Q11-R11-S11 -> 49554.971 | U11: =W10 -> 0 | V11: =MIN(U11+I11,MAX(T11,0)) -> 29850.291 | W11: =U11+I11-V11 -> 0 | X11: =K11+L11+V11+IF(E11,H11-I11-K11-L11,0) -> 3474418.4 | Y11: =AND(Inputs!$C$21=1,O11/Inputs!$C$10<=Inputs!$C$22,Inputs!$G$14<Inputs!$C$23,W11<1) -> TRUE | Z11: =OR(AND(Inputs!$G$15=1,H11/Inputs!$C$17<=Inputs!$C$24),AND(Inputs!$G$15=2,C11>=Inputs!$G$16)) -> FALSE | AA11: =OR(AA10,Z11) -> FALSE | AB11: =AND(Z11,NOT(AA10),D11,O11>0) -> FALSE | AC11: =IF(AND(Y11,NOT(E11),O11+P11>0),O11/(O11+P11),1) -> 0.92871669 | AD11: =IF(AB11,O11,IF(D11,MIN(O11,IF(E11,AC11*X11+BF10,BE11*Inputs!$G$20)),0)) -> 3226750.4 | AE11: =IF(AB11,P11,IF(D11,MAX(MIN(P11,X11-MIN(O11,AC11*X11)),0),0)) -> 247668.04 | AF11: =IF(OR(AB11,E11),0,MAX(H11-I11-K11-L11,0)) -> 1.1588196e+08 | AG11: =IF(E11,0,O11-AD11) -> 1.0761832e+08 | AH11: =IF(OR(AB11,E11),0,P11-AE11) -> 8260204.5 | AI11: =IF(D11,R11+AD11,0) -> 3930591.9 | AJ11: =(C11-Inputs!$G$6)/365 -> 0.14520548 | AK11: =AG11/Inputs!$C$10 -> 0.076122595 | AM11: =(C11-Inputs!$G$6)/360 -> 0.14722222 | AO11: =0+LN(1+($G11+AO$7)*$AM11) -> 0.0036914006 | AP11: =0+LN(1+($G11+AP$7)*$AM11) -> 0.0037060685 | AQ11: =0+LN(1+($G11+AQ$7)*$AM11) -> 0.0041773005 | AR11: =0+LN(1+($G11+AR$7)*$AM11) -> 0.0041919613 | AS11: =0+LN(1+($G11+AS$7)*$AM11) -> 0.0041826297 | AT11: =0+LN(1+($G11+AT$7)*$AM11) -> 0.0041972903 | AU11: =0+LN(1+($G11+AU$7)*$AM11) -> 0.0041826285 | AV11: =0+LN(1+($G11+AV$7)*$AM11) -> 0.0041972892 | ... BD11: =0+LN(1+($G11+BD$7)*$AM11) -> 0.0041972892 | BE11: =IF(AB11,O11,IF(D11,MIN(O11,AC11*X11+BF10),0)) -> 3226750.4 | BF11: =IF(OR(AB11,E11),0,BE11-AD11) -> 0 | BG11: =0+LN(1+($G11+BG$7)*$AM11) -> 0.0040360101 | BI11: =0+LN(1+($G11+BI$7)*$AM11) -> 0.0043292255 | BK11: =C11 -> 46342 | BL11: =AI11 -> 3930591.9
A12: 2 | B12: =EDATE(Inputs!$C$8,3*(A12-1)) -> 46433 | C12: =WORKDAY(B12-1,1) -> 46433 | D12: =C12<=Inputs!$C$9 -> TRUE | E12: =AND(D12,NOT(D13)) -> FALSE | F12: =(C12-C11)/360 -> 0.25277778 | G12: =Curve!D5 -> 0.02252 | H12: =AF11 -> 1.1588196e+08 | I12: =IF(D12,H12*Inputs!$G$22,0) -> 28981.361 | J12: =MAX(Inputs!$G$24-(A12-1),1) -> 44.59177 | K12: =IF(D12,MIN(H12-I12,IF(J12>1,(H12-I12)*Inputs!$G$23/((1+Inputs!$G$23)^J12-1),H12-I12)),0) -> 2175671.3 | L12: =IF(D12,(H12-I12-K12)*Inputs!$G$21,0) -> 1224626.8 | M12: =IF(A12>Inputs!$G$13,(1-Inputs!$G$12)*INDEX($I$11:$I$190,A12-Inputs!$G$13),0) -> 0 | N12: =IF(D12,(H12-I12)*Inputs!$G$23,0) -> 919293.4 | O12: =AG11 -> 1.0761832e+08 | P12: =AH11 -> 8260204.5 | Q12: =IF(AND(D12,O12+P12>0),Inputs!$C$25+Inputs!$C$26*H12/4,0) -> 128970.49 | R12: =O12*IF(Inputs!$G$19="",G12+Inputs!$C$13,MAX(Inputs!$G$19,G12+Inputs!$C$13))*F12 -> 683352.41 | S12: =P12*(G12+Inputs!$C$14)*F12 -> 61768.372 | T12: =N12+M12-Q12-R12-S12 -> 45202.126 | U12: =W11 -> 0 | V12: =MIN(U12+I12,MAX(T12,0)) -> 28981.361 | W12: =U12+I12-V12 -> 0 | X12: =K12+L12+V12+IF(E12,H12-I12-K12-L12,0) -> 3429279.4 | Y12: =AND(Inputs!$C$21=1,O12/Inputs!$C$10<=Inputs!$C$22,Inputs!$G$14<Inputs!$C$23,W12<1) -> TRUE | Z12: =OR(AND(Inputs!$G$15=1,H12/Inputs!$C$17<=Inputs!$C$24),AND(Inputs!$G$15=2,C12>=Inputs!$G$16)) -> FALSE | AA12: =OR(AA11,Z12) -> FALSE | AB12: =AND(Z12,NOT(AA11),D12,O12>0) -> FALSE | AC12: =IF(AND(Y12,NOT(E12),O12+P12>0),O12/(O12+P12),1) -> 0.92871669 | AD12: =IF(AB12,O12,IF(D12,MIN(O12,IF(E12,AC12*X12+BF11,BE12*Inputs!$G$20)),0)) -> 3184829.1 | AE12: =IF(AB12,P12,IF(D12,MAX(MIN(P12,X12-MIN(O12,AC12*X12)),0),0)) -> 244450.38 | AF12: =IF(OR(AB12,E12),0,MAX(H12-I12-K12-L12,0)) -> 1.1245268e+08 | AG12: =IF(E12,0,O12-AD12) -> 1.0443349e+08 | AH12: =IF(OR(AB12,E12),0,P12-AE12) -> 8015754.1 | AI12: =IF(D12,R12+AD12,0) -> 3868181.5 | AJ12: =(C12-Inputs!$G$6)/365 -> 0.39452055 | AK12: =AG12/Inputs!$C$10 -> 0.073869842 | AM12: =F12 -> 0.25277778 | AO12: =AO11+LN(1+($G12+AO$7)*$AM12) -> 0.010021103 | AP12: =AP11+LN(1+($G12+AP$7)*$AM12) -> 0.010060889 | AQ12: =AQ11+LN(1+($G12+AQ$7)*$AM12) -> 0.011338942 | AR12: =AR11+LN(1+($G12+AR$7)*$AM12) -> 0.0113787 | AS12: =AS11+LN(1+($G12+AS$7)*$AM12) -> 0.011353394 | AT12: =AT11+LN(1+($G12+AT$7)*$AM12) -> 0.011393152 | AU12: =AU11+LN(1+($G12+AU$7)*$AM12) -> 0.011353391 | AV12: =AV11+LN(1+($G12+AV$7)*$AM12) -> 0.011393149 | ... BD12: =BD11+LN(1+($G12+BD$7)*$AM12) -> 0.011393149 | BE12: =IF(AB12,O12,IF(D12,MIN(O12,AC12*X12+BF11),0)) -> 3184829.1 | BF12: =IF(OR(AB12,E12),0,BE12-AD12) -> 0 | BG12: =BG11+LN(1+($G12+BG$7)*$AM12) -> 0.010955769 | BI12: =BI11+LN(1+($G12+BI$7)*$AM12) -> 0.011750928 | BK12: =C12 -> 46433 | BL12: =AI12 -> 3868181.5
A13: 3 | B13: =EDATE(Inputs!$C$8,3*(A13-1)) -> 46522 | C13: =WORKDAY(B13-1,1) -> 46524 | D13: =C13<=Inputs!$C$9 -> TRUE | E13: =AND(D13,NOT(D14)) -> FALSE | F13: =(C13-C12)/360 -> 0.25277778 | G13: =Curve!D6 -> 0.02252 | H13: =AF12 -> 1.1245268e+08 | I13: =IF(D13,H13*Inputs!$G$22,0) -> 28123.719 | J13: =MAX(Inputs!$G$24-(A13-1),1) -> 43.59177 | K13: =IF(D13,MIN(H13-I13,IF(J13>1,(H13-I13)*Inputs!$G$23/((1+Inputs!$G$23)^J13-1),H13-I13)),0) -> 2168768.6 | L13: =IF(D13,(H13-I13-K13)*Inputs!$G$21,0) -> 1187767.3 | M13: =IF(A13>Inputs!$G$13,(1-Inputs!$G$12)*INDEX($I$11:$I$190,A13-Inputs!$G$13),0) -> 0 | N13: =IF(D13,(H13-I13)*Inputs!$G$23,0) -> 892088.87 | O13: =AG12 -> 1.0443349e+08 | P13: =AH12 -> 8015754.1 | Q13: =IF(AND(D13,O13+P13>0),Inputs!$C$25+Inputs!$C$26*H13/4,0) -> 128113.17 | R13: =O13*IF(Inputs!$G$19="",G13+Inputs!$C$13,MAX(Inputs!$G$19,G13+Inputs!$C$13))*F13 -> 663129.45 | S13: =P13*(G13+Inputs!$C$14)*F13 -> 59940.415 | T13: =N13+M13-Q13-R13-S13 -> 40905.833 | U13: =W12 -> 0 | V13: =MIN(U13+I13,MAX(T13,0)) -> 28123.719 | W13: =U13+I13-V13 -> 0 | X13: =K13+L13+V13+IF(E13,H13-I13-K13-L13,0) -> 3384659.6 | Y13: =AND(Inputs!$C$21=1,O13/Inputs!$C$10<=Inputs!$C$22,Inputs!$G$14<Inputs!$C$23,W13<1) -> TRUE | Z13: =OR(AND(Inputs!$G$15=1,H13/Inputs!$C$17<=Inputs!$C$24),AND(Inputs!$G$15=2,C13>=Inputs!$G$16)) -> FALSE | AA13: =OR(AA12,Z13) -> FALSE | AB13: =AND(Z13,NOT(AA12),D13,O13>0) -> FALSE | AC13: =IF(AND(Y13,NOT(E13),O13+P13>0),O13/(O13+P13),1) -> 0.92871669 | AD13: =IF(AB13,O13,IF(D13,MIN(O13,IF(E13,AC13*X13+BF12,BE13*Inputs!$G$20)),0)) -> 3143389.9 | AE13: =IF(AB13,P13,IF(D13,MAX(MIN(P13,X13-MIN(O13,AC13*X13)),0),0)) -> 241269.74 | AF13: =IF(OR(AB13,E13),0,MAX(H13-I13-K13-L13,0)) -> 1.0906802e+08 | AG13: =IF(E13,0,O13-AD13) -> 1.012901e+08 | AH13: =IF(OR(AB13,E13),0,P13-AE13) -> 7774484.3 | AI13: =IF(D13,R13+AD13,0) -> 3806519.4 | AJ13: =(C13-Inputs!$G$6)/365 -> 0.64383562 | AK13: =AG13/Inputs!$C$10 -> 0.071646401 | AM13: =F13 -> 0.25277778 | AO13: =AO12+LN(1+($G13+AO$7)*$AM13) -> 0.016350806 | AP13: =AP12+LN(1+($G13+AP$7)*$AM13) -> 0.01641571 | AQ13: =AQ12+LN(1+($G13+AQ$7)*$AM13) -> 0.018500584 | AR13: =AR12+LN(1+($G13+AR$7)*$AM13) -> 0.018565439 | AS13: =AS12+LN(1+($G13+AS$7)*$AM13) -> 0.018524159 | AT13: =AT12+LN(1+($G13+AT$7)*$AM13) -> 0.018589013 | AU13: =AU12+LN(1+($G13+AU$7)*$AM13) -> 0.018524154 | AV13: =AV12+LN(1+($G13+AV$7)*$AM13) -> 0.018589008 | ... BD13: =BD12+LN(1+($G13+BD$7)*$AM13) -> 0.018589008 | BE13: =IF(AB13,O13,IF(D13,MIN(O13,AC13*X13+BF12),0)) -> 3143389.9 | BF13: =IF(OR(AB13,E13),0,BE13-AD13) -> 0 | BG13: =BG12+LN(1+($G13+BG$7)*$AM13) -> 0.017875529 | BI13: =BI12+LN(1+($G13+BI$7)*$AM13) -> 0.019172631 | BK13: =C13 -> 46524 | BL13: =AI13 -> 3806519.4
A14: 4 | B14: =EDATE(Inputs!$C$8,3*(A14-1)) -> 46614 | C14: =WORKDAY(B14-1,1) -> 46615 | D14: =C14<=Inputs!$C$9 -> TRUE | E14: =AND(D14,NOT(D15)) -> FALSE | F14: =(C14-C13)/360 -> 0.25277778 | G14: =Curve!D7 -> 0.02252 | H14: =AF13 -> 1.0906802e+08 | I14: =IF(D14,H14*Inputs!$G$22,0) -> 27277.237 | J14: =MAX(Inputs!$G$24-(A14-1),1) -> 42.59177 | K14: =IF(D14,MIN(H14-I14,IF(J14>1,(H14-I14)*Inputs!$G$23/((1+Inputs!$G$23)^J14-1),H14-I14)),0) -> 2161887.8 | L14: =IF(D14,(H14-I14-K14)*Inputs!$G$21,0) -> 1151388.2 | M14: =IF(A14>Inputs!$G$13,(1-Inputs!$G$12)*INDEX($I$11:$I$190,A14-Inputs!$G$13),0) -> 0 | N14: =IF(D14,(H14-I14)*Inputs!$G$23,0) -> 865238.31 | O14: =AG13 -> 1.012901e+08 | P14: =AH13 -> 7774484.3 | Q14: =IF(AND(D14,O14+P14>0),Inputs!$C$25+Inputs!$C$26*H14/4,0) -> 127267.01 | R14: =O14*IF(Inputs!$G$19="",G14+Inputs!$C$13,MAX(Inputs!$G$19,G14+Inputs!$C$13))*F14 -> 643169.62 | S14: =P14*(G14+Inputs!$C$14)*F14 -> 58136.242 | T14: =N14+M14-Q14-R14-S14 -> 36665.441 | U14: =W13 -> 0 | V14: =MIN(U14+I14,MAX(T14,0)) -> 27277.237 | W14: =U14+I14-V14 -> 0 | X14: =K14+L14+V14+IF(E14,H14-I14-K14-L14,0) -> 3340553.2 | Y14: =AND(Inputs!$C$21=1,O14/Inputs!$C$10<=Inputs!$C$22,Inputs!$G$14<Inputs!$C$23,W14<1) -> TRUE | Z14: =OR(AND(Inputs!$G$15=1,H14/Inputs!$C$17<=Inputs!$C$24),AND(Inputs!$G$15=2,C14>=Inputs!$G$16)) -> FALSE | AA14: =OR(AA13,Z14) -> FALSE | AB14: =AND(Z14,NOT(AA13),D14,O14>0) -> FALSE | AC14: =IF(AND(Y14,NOT(E14),O14+P14>0),O14/(O14+P14),1) -> 0.92871669 | AD14: =IF(AB14,O14,IF(D14,MIN(O14,IF(E14,AC14*X14+BF13,BE14*Inputs!$G$20)),0)) -> 3102427.5 | AE14: =IF(AB14,P14,IF(D14,MAX(MIN(P14,X14-MIN(O14,AC14*X14)),0),0)) -> 238125.68 | AF14: =IF(OR(AB14,E14),0,MAX(H14-I14-K14-L14,0)) -> 1.0572747e+08 | AG14: =IF(E14,0,O14-AD14) -> 98187672 | AH14: =IF(OR(AB14,E14),0,P14-AE14) -> 7536358.7 | AI14: =IF(D14,R14+AD14,0) -> 3745597.2 | AJ14: =(C14-Inputs!$G$6)/365 -> 0.89315068 | AK14: =AG14/Inputs!$C$10 -> 0.069451934 | AM14: =F14 -> 0.25277778 | AO14: =AO13+LN(1+($G14+AO$7)*$AM14) -> 0.022680509 | AP14: =AP13+LN(1+($G14+AP$7)*$AM14) -> 0.022770531 | AQ14: =AQ13+LN(1+($G14+AQ$7)*$AM14) -> 0.025662226 | AR14: =AR13+LN(1+($G14+AR$7)*$AM14) -> 0.025752178 | AS14: =AS13+LN(1+($G14+AS$7)*$AM14) -> 0.025694923 | AT14: =AT13+LN(1+($G14+AT$7)*$AM14) -> 0.025784874 | AU14: =AU13+LN(1+($G14+AU$7)*$AM14) -> 0.025694916 | AV14: =AV13+LN(1+($G14+AV$7)*$AM14) -> 0.025784867 | ... BD14: =BD13+LN(1+($G14+BD$7)*$AM14) -> 0.025784867 | BE14: =IF(AB14,O14,IF(D14,MIN(O14,AC14*X14+BF13),0)) -> 3102427.5 | BF14: =IF(OR(AB14,E14),0,BE14-AD14) -> 0 | BG14: =BG13+LN(1+($G14+BG$7)*$AM14) -> 0.024795288 | BI14: =BI13+LN(1+($G14+BI$7)*$AM14) -> 0.026594334 | BK14: =C14 -> 46615 | BL14: =AI14 -> 3745597.2
A15: 5 | B15: =EDATE(Inputs!$C$8,3*(A15-1)) -> 46706 | C15: =WORKDAY(B15-1,1) -> 46706 | D15: =C15<=Inputs!$C$9 -> TRUE | E15: =AND(D15,NOT(D16)) -> FALSE | F15: =(C15-C14)/360 -> 0.25277778 | G15: =Curve!D8 -> 0.02252 | H15: =AF14 -> 1.0572747e+08 | I15: =IF(D15,H15*Inputs!$G$22,0) -> 26441.785 | J15: =MAX(Inputs!$G$24-(A15-1),1) -> 41.59177 | K15: =IF(D15,MIN(H15-I15,IF(J15>1,(H15-I15)*Inputs!$G$23/((1+Inputs!$G$23)^J15-1),H15-I15)),0) -> 2155028.8 | L15: =IF(D15,(H15-I15-K15)*Inputs!$G$21,0) -> 1115483.9 | M15: =IF(A15>Inputs!$G$13,(1-Inputs!$G$12)*INDEX($I$11:$I$190,A15-Inputs!$G$13),0) -> 0 | N15: =IF(D15,(H15-I15)*Inputs!$G$23,0) -> 838737.65 | O15: =AG14 -> 98187672 | P15: =AH14 -> 7536358.7 | Q15: =IF(AND(D15,O15+P15>0),Inputs!$C$25+Inputs!$C$26*H15/4,0) -> 126431.87 | R15: =O15*IF(Inputs!$G$19="",G15+Inputs!$C$13,MAX(Inputs!$G$19,G15+Inputs!$C$13))*F15 -> 623469.9 | S15: =P15*(G15+Inputs!$C$14)*F15 -> 56355.579 | T15: =N15+M15-Q15-R15-S15 -> 32480.307 | U15: =W14 -> 0 | V15: =MIN(U15+I15,MAX(T15,0)) -> 26441.785 | W15: =U15+I15-V15 -> 0 | X15: =K15+L15+V15+IF(E15,H15-I15-K15-L15,0) -> 3296954.5 | Y15: =AND(Inputs!$C$21=1,O15/Inputs!$C$10<=Inputs!$C$22,Inputs!$G$14<Inputs!$C$23,W15<1) -> TRUE | Z15: =OR(AND(Inputs!$G$15=1,H15/Inputs!$C$17<=Inputs!$C$24),AND(Inputs!$G$15=2,C15>=Inputs!$G$16)) -> FALSE | AA15: =OR(AA14,Z15) -> FALSE | AB15: =AND(Z15,NOT(AA14),D15,O15>0) -> FALSE | AC15: =IF(AND(Y15,NOT(E15),O15+P15>0),O15/(O15+P15),1) -> 0.92871669 | AD15: =IF(AB15,O15,IF(D15,MIN(O15,IF(E15,AC15*X15+BF14,BE15*Inputs!$G$20)),0)) -> 3061936.6 | AE15: =IF(AB15,P15,IF(D15,MAX(MIN(P15,X15-MIN(O15,AC15*X15)),0),0)) -> 235017.82 | AF15: =IF(OR(AB15,E15),0,MAX(H15-I15-K15-L15,0)) -> 1.0243051e+08 | AG15: =IF(E15,0,O15-AD15) -> 95125735 | AH15: =IF(OR(AB15,E15),0,P15-AE15) -> 7301340.8 | AI15: =IF(D15,R15+AD15,0) -> 3685406.5 | AJ15: =(C15-Inputs!$G$6)/365 -> 1.1424658 | AK15: =AG15/Inputs!$C$10 -> 0.067286108 | AM15: =F15 -> 0.25277778 | AO15: =AO14+LN(1+($G15+AO$7)*$AM15) -> 0.029010212 | AP15: =AP14+LN(1+($G15+AP$7)*$AM15) -> 0.029125352 | AQ15: =AQ14+LN(1+($G15+AQ$7)*$AM15) -> 0.032823867 | AR15: =AR14+LN(1+($G15+AR$7)*$AM15) -> 0.032938916 | AS15: =AS14+LN(1+($G15+AS$7)*$AM15) -> 0.032865688 | AT15: =AT14+LN(1+($G15+AT$7)*$AM15) -> 0.032980736 | AU15: =AU14+LN(1+($G15+AU$7)*$AM15) -> 0.032865679 | AV15: =AV14+LN(1+($G15+AV$7)*$AM15) -> 0.032980727 | ... BD15: =BD14+LN(1+($G15+BD$7)*$AM15) -> 0.032980727 | BE15: =IF(AB15,O15,IF(D15,MIN(O15,AC15*X15+BF14),0)) -> 3061936.6 | BF15: =IF(OR(AB15,E15),0,BE15-AD15) -> 0 | BG15: =BG14+LN(1+($G15+BG$7)*$AM15) -> 0.031715048 | BI15: =BI14+LN(1+($G15+BI$7)*$AM15) -> 0.034016036 | BK15: =C15 -> 46706 | BL15: =AI15 -> 3685406.5
A16: 6 | B16: =EDATE(Inputs!$C$8,3*(A16-1)) -> 46798 | C16: =WORKDAY(B16-1,1) -> 46798 | D16: =C16<=Inputs!$C$9 -> TRUE | E16: =AND(D16,NOT(D17)) -> FALSE | F16: =(C16-C15)/360 -> 0.25555556 | G16: =Curve!D9 -> 0.02252 | H16: =AF15 -> 1.0243051e+08 | I16: =IF(D16,H16*Inputs!$G$22,0) -> 25617.237 | J16: =MAX(Inputs!$G$24-(A16-1),1) -> 40.59177 | K16: =IF(D16,MIN(H16-I16,IF(J16>1,(H16-I16)*Inputs!$G$23/((1+Inputs!$G$23)^J16-1),H16-I16)),0) -> 2148191.6 | L16: =IF(D16,(H16-I16-K16)*Inputs!$G$21,0) -> 1080048.9 | M16: =IF(A16>Inputs!$G$13,(1-Inputs!$G$12)*INDEX($I$11:$I$190,A16-Inputs!$G$13),0) -> 0 | N16: =IF(D16,(H16-I16)*Inputs!$G$23,0) -> 812582.86 | O16: =AG15 -> 95125735 | P16: =AH15 -> 7301340.8 | Q16: =IF(AND(D16,O16+P16>0),Inputs!$C$25+Inputs!$C$26*H16/4,0) -> 125607.63 | R16: =O16*IF(Inputs!$G$19="",G16+Inputs!$C$13,MAX(Inputs!$G$19,G16+Inputs!$C$13))*F16 -> 610664.94 | S16: =P16*(G16+Inputs!$C$14)*F16 -> 55198.137 | T16: =N16+M16-Q16-R16-S16 -> 21112.152 | U16: =W15 -> 0 | V16: =MIN(U16+I16,MAX(T16,0)) -> 21112.152 | W16: =U16+I16-V16 -> 4505.0847 | X16: =K16+L16+V16+IF(E16,H16-I16-K16-L16,0) -> 3249352.6 | Y16: =AND(Inputs!$C$21=1,O16/Inputs!$C$10<=Inputs!$C$22,Inputs!$G$14<Inputs!$C$23,W16<1) -> FALSE | Z16: =OR(AND(Inputs!$G$15=1,H16/Inputs!$C$17<=Inputs!$C$24),AND(Inputs!$G$15=2,C16>=Inputs!$G$16)) -> FALSE | AA16: =OR(AA15,Z16) -> FALSE | AB16: =AND(Z16,NOT(AA15),D16,O16>0) -> FALSE | AC16: =IF(AND(Y16,NOT(E16),O16+P16>0),O16/(O16+P16),1) -> 1 | AD16: =IF(AB16,O16,IF(D16,MIN(O16,IF(E16,AC16*X16+BF15,BE16*Inputs!$G$20)),0)) -> 3249352.6 | AE16: =IF(AB16,P16,IF(D16,MAX(MIN(P16,X16-MIN(O16,AC16*X16)),0),0)) -> 0 | AF16: =IF(OR(AB16,E16),0,MAX(H16-I16-K16-L16,0)) -> 99176657 | AG16: =IF(E16,0,O16-AD16) -> 91876383 | AH16: =IF(OR(AB16,E16),0,P16-AE16) -> 7301340.8 | AI16: =IF(D16,R16+AD16,0) -> 3860017.5 | AJ16: =(C16-Inputs!$G$6)/365 -> 1.3945205 | AK16: =AG16/Inputs!$C$10 -> 0.064987715 | AM16: =F16 -> 0.25555556 | AO16: =AO15+LN(1+($G16+AO$7)*$AM16) -> 0.03540925 | AP16: =AP15+LN(1+($G16+AP$7)*$AM16) -> 0.035549782 | AQ16: =AQ15+LN(1+($G16+AQ$7)*$AM16) -> 0.040063924 | AR16: =AR15+LN(1+($G16+AR$7)*$AM16) -> 0.040204344 | AS16: =AS15+LN(1+($G16+AS$7)*$AM16) -> 0.040114967 | AT16: =AT15+LN(1+($G16+AT$7)*$AM16) -> 0.040255385 | AU16: =AU15+LN(1+($G16+AU$7)*$AM16) -> 0.040114956 | AV16: =AV15+LN(1+($G16+AV$7)*$AM16) -> 0.040255375 | ... BD16: =BD15+LN(1+($G16+BD$7)*$AM16) -> 0.040255375 | BE16: =IF(AB16,O16,IF(D16,MIN(O16,AC16*X16+BF15),0)) -> 3249352.6 | BF16: =IF(OR(AB16,E16),0,BE16-AD16) -> 0 | BG16: =BG15+LN(1+($G16+BG$7)*$AM16) -> 0.038710583 | BI16: =BI15+LN(1+($G16+BI$7)*$AM16) -> 0.041518991 | BK16: =C16 -> 46798 | BL16: =AI16 -> 3860017.5
A17: 7 | B17: =EDATE(Inputs!$C$8,3*(A17-1)) -> 46888 | C17: =WORKDAY(B17-1,1) -> 46888 | D17: =C17<=Inputs!$C$9 -> TRUE | E17: =AND(D17,NOT(D18)) -> FALSE | F17: =(C17-C16)/360 -> 0.25 | G17: =Curve!D10 -> 0.02252 | H17: =AF16 -> 99176657 | I17: =IF(D17,H17*Inputs!$G$22,0) -> 24803.467 | J17: =MAX(Inputs!$G$24-(A17-1),1) -> 39.59177 | K17: =IF(D17,MIN(H17-I17,IF(J17>1,(H17-I17)*Inputs!$G$23/((1+Inputs!$G$23)^J17-1),H17-I17)),0) -> 2141376.1 | L17: =IF(D17,(H17-I17-K17)*Inputs!$G$21,0) -> 1045077.8 | M17: =IF(A17>Inputs!$G$13,(1-Inputs!$G$12)*INDEX($I$11:$I$190,A17-Inputs!$G$13),0) -> 0 | N17: =IF(D17,(H17-I17)*Inputs!$G$23,0) -> 786769.96 | O17: =AG16 -> 91876383 | P17: =AH16 -> 7301340.8 | Q17: =IF(AND(D17,O17+P17>0),Inputs!$C$25+Inputs!$C$26*H17/4,0) -> 124794.16 | R17: =O17*IF(Inputs!$G$19="",G17+Inputs!$C$13,MAX(Inputs!$G$19,G17+Inputs!$C$13))*F17 -> 576983.68 | S17: =P17*(G17+Inputs!$C$14)*F17 -> 53998.177 | T17: =N17+M17-Q17-R17-S17 -> 30993.932 | U17: =W16 -> 4505.0847 | V17: =MIN(U17+I17,MAX(T17,0)) -> 29308.552 | W17: =U17+I17-V17 -> 0 | X17: =K17+L17+V17+IF(E17,H17-I17-K17-L17,0) -> 3215762.4 | Y17: =AND(Inputs!$C$21=1,O17/Inputs!$C$10<=Inputs!$C$22,Inputs!$G$14<Inputs!$C$23,W17<1) -> TRUE | Z17: =OR(AND(Inputs!$G$15=1,H17/Inputs!$C$17<=Inputs!$C$24),AND(Inputs!$G$15=2,C17>=Inputs!$G$16)) -> FALSE | AA17: =OR(AA16,Z17) -> FALSE | AB17: =AND(Z17,NOT(AA16),D17,O17>0) -> FALSE | AC17: =IF(AND(Y17,NOT(E17),O17+P17>0),O17/(O17+P17),1) -> 0.92638124 | AD17: =IF(AB17,O17,IF(D17,MIN(O17,IF(E17,AC17*X17+BF16,BE17*Inputs!$G$20)),0)) -> 2979022 | AE17: =IF(AB17,P17,IF(D17,MAX(MIN(P17,X17-MIN(O17,AC17*X17)),0),0)) -> 236740.43 | AF17: =IF(OR(AB17,E17),0,MAX(H17-I17-K17-L17,0)) -> 95965399 | AG17: =IF(E17,0,O17-AD17) -> 88897361 | AH17: =IF(OR(AB17,E17),0,P17-AE17) -> 7064600.4 | AI17: =IF(D17,R17+AD17,0) -> 3556005.7 | AJ17: =(C17-Inputs!$G$6)/365 -> 1.6410959 | AK17: =AG17/Inputs!$C$10 -> 0.062880538 | AM17: =F17 -> 0.25 | AO17: =AO16+LN(1+($G17+AO$7)*$AM17) -> 0.041669613 | AP17: =AP16+LN(1+($G17+AP$7)*$AM17) -> 0.041834989 | AQ17: =AQ16+LN(1+($G17+AQ$7)*$AM17) -> 0.047147144 | AR17: =AR16+LN(1+($G17+AR$7)*$AM17) -> 0.047312388 | AS17: =AS16+LN(1+($G17+AS$7)*$AM17) -> 0.04720721 | AT17: =AT16+LN(1+($G17+AT$7)*$AM17) -> 0.047372452 | AU17: =AU16+LN(1+($G17+AU$7)*$AM17) -> 0.047207198 | AV17: =AV16+LN(1+($G17+AV$7)*$AM17) -> 0.047372439 | ... BD17: =BD16+LN(1+($G17+BD$7)*$AM17) -> 0.047372439 | BE17: =IF(AB17,O17,IF(D17,MIN(O17,AC17*X17+BF16),0)) -> 2979022 | BF17: =IF(OR(AB17,E17),0,BE17-AD17) -> 0 | BG17: =BG16+LN(1+($G17+BG$7)*$AM17) -> 0.045554561 | BI17: =BI16+LN(1+($G17+BI$7)*$AM17) -> 0.048859435 | BK17: =C17 -> 46888 | BL17: =AI17 -> 3556005.7
A18: 8 | B18: =EDATE(Inputs!$C$8,3*(A18-1)) -> 46980 | C18: =WORKDAY(B18-1,1) -> 46980 | D18: =C18<=Inputs!$C$9 -> TRUE | E18: =AND(D18,NOT(D19)) -> FALSE | F18: =(C18-C17)/360 -> 0.25555556 | G18: =Curve!D11 -> 0.02252 | H18: =AF17 -> 95965399 | I18: =IF(D18,H18*Inputs!$G$22,0) -> 24000.352 | J18: =MAX(Inputs!$G$24-(A18-1),1) -> 38.59177 | K18: =IF(D18,MIN(H18-I18,IF(J18>1,(H18-I18)*Inputs!$G$23/((1+Inputs!$G$23)^J18-1),H18-I18)),0) -> 2134582.2 | L18: =IF(D18,(H18-I18-K18)*Inputs!$G$21,0) -> 1010565.3 | M18: =IF(A18>Inputs!$G$13,(1-Inputs!$G$12)*INDEX($I$11:$I$190,A18-Inputs!$G$13),0) -> 0 | N18: =IF(D18,(H18-I18)*Inputs!$G$23,0) -> 761295 | O18: =AG17 -> 88897361 | P18: =AH17 -> 7064600.4 | Q18: =IF(AND(D18,O18+P18>0),Inputs!$C$25+Inputs!$C$26*H18/4,0) -> 123991.35 | R18: =O18*IF(Inputs!$G$19="",G18+Inputs!$C$13,MAX(Inputs!$G$19,G18+Inputs!$C$13))*F18 -> 570681.55 | S18: =P18*(G18+Inputs!$C$14)*F18 -> 53408.379 | T18: =N18+M18-Q18-R18-S18 -> 13213.728 | U18: =W17 -> 0 | V18: =MIN(U18+I18,MAX(T18,0)) -> 13213.728 | W18: =U18+I18-V18 -> 10786.624 | X18: =K18+L18+V18+IF(E18,H18-I18-K18-L18,0) -> 3158361.2 | Y18: =AND(Inputs!$C$21=1,O18/Inputs!$C$10<=Inputs!$C$22,Inputs!$G$14<Inputs!$C$23,W18<1) -> FALSE | Z18: =OR(AND(Inputs!$G$15=1,H18/Inputs!$C$17<=Inputs!$C$24),AND(Inputs!$G$15=2,C18>=Inputs!$G$16)) -> FALSE | AA18: =OR(AA17,Z18) -> FALSE | AB18: =AND(Z18,NOT(AA17),D18,O18>0) -> FALSE | AC18: =IF(AND(Y18,NOT(E18),O18+P18>0),O18/(O18+P18),1) -> 1 | AD18: =IF(AB18,O18,IF(D18,MIN(O18,IF(E18,AC18*X18+BF17,BE18*Inputs!$G$20)),0)) -> 3158361.2 | AE18: =IF(AB18,P18,IF(D18,MAX(MIN(P18,X18-MIN(O18,AC18*X18)),0),0)) -> 0 | AF18: =IF(OR(AB18,E18),0,MAX(H18-I18-K18-L18,0)) -> 92796252 | AG18: =IF(E18,0,O18-AD18) -> 85738999 | AH18: =IF(OR(AB18,E18),0,P18-AE18) -> 7064600.4 | AI18: =IF(D18,R18+AD18,0) -> 3729042.7 | AJ18: =(C18-Inputs!$G$6)/365 -> 1.8931507 | AK18: =AG18/Inputs!$C$10 -> 0.060646507 | AM18: =F18 -> 0.25555556 | AO18: =AO17+LN(1+($G18+AO$7)*$AM18) -> 0.048068651 | AP18: =AP17+LN(1+($G18+AP$7)*$AM18) -> 0.048259419 | AQ18: =AQ17+LN(1+($G18+AQ$7)*$AM18) -> 0.054387201 | AR18: =AR17+LN(1+($G18+AR$7)*$AM18) -> 0.054577815 | AS18: =AS17+LN(1+($G18+AS$7)*$AM18) -> 0.05445649 | AT18: =AT17+LN(1+($G18+AT$7)*$AM18) -> 0.054647102 | AU18: =AU17+LN(1+($G18+AU$7)*$AM18) -> 0.054456475 | AV18: =AV17+LN(1+($G18+AV$7)*$AM18) -> 0.054647087 | ... BD18: =BD17+LN(1+($G18+BD$7)*$AM18) -> 0.054647087 | BE18: =IF(AB18,O18,IF(D18,MIN(O18,AC18*X18+BF17),0)) -> 3158361.2 | BF18: =IF(OR(AB18,E18),0,BE18-AD18) -> 0 | BG18: =BG17+LN(1+($G18+BG$7)*$AM18) -> 0.052550096 | BI18: =BI17+LN(1+($G18+BI$7)*$AM18) -> 0.05636239 | BK18: =C18 -> 46980 | BL18: =AI18 -> 3729042.7
A19: 9 | B19: =EDATE(Inputs!$C$8,3*(A19-1)) -> 47072 | C19: =WORKDAY(B19-1,1) -> 47072 | D19: =C19<=Inputs!$C$9 -> TRUE | E19: =AND(D19,NOT(D20)) -> FALSE | F19: =(C19-C18)/360 -> 0.25555556 | G19: =Curve!D12 -> 0.02252 | H19: =AF18 -> 92796252 | I19: =IF(D19,H19*Inputs!$G$22,0) -> 23207.768 | J19: =MAX(Inputs!$G$24-(A19-1),1) -> 37.59177 | K19: =IF(D19,MIN(H19-I19,IF(J19>1,(H19-I19)*Inputs!$G$23/((1+Inputs!$G$23)^J19-1),H19-I19)),0) -> 2127809.8 | L19: =IF(D19,(H19-I19-K19)*Inputs!$G$21,0) -> 976506.07 | M19: =IF(A19>Inputs!$G$13,(1-Inputs!$G$12)*INDEX($I$11:$I$190,A19-Inputs!$G$13),0) -> 23880.233 | N19: =IF(D19,(H19-I19)*Inputs!$G$23,0) -> 736154.1 | O19: =AG18 -> 85738999 | P19: =AH18 -> 7064600.4 | Q19: =IF(AND(D19,O19+P19>0),Inputs!$C$25+Inputs!$C$26*H19/4,0) -> 123199.06 | R19: =O19*IF(Inputs!$G$19="",G19+Inputs!$C$13,MAX(Inputs!$G$19,G19+Inputs!$C$13))*F19 -> 550406.27 | S19: =P19*(G19+Inputs!$C$14)*F19 -> 53408.379 | T19: =N19+M19-Q19-R19-S19 -> 33020.624 | U19: =W18 -> 10786.624 | V19: =MIN(U19+I19,MAX(T19,0)) -> 33020.624 | W19: =U19+I19-V19 -> 973.76764 | X19: =K19+L19+V19+IF(E19,H19-I19-K19-L19,0) -> 3137336.5 | Y19: =AND(Inputs!$C$21=1,O19/Inputs!$C$10<=Inputs!$C$22,Inputs!$G$14<Inputs!$C$23,W19<1) -> FALSE | Z19: =OR(AND(Inputs!$G$15=1,H19/Inputs!$C$17<=Inputs!$C$24),AND(Inputs!$G$15=2,C19>=Inputs!$G$16)) -> FALSE | AA19: =OR(AA18,Z19) -> FALSE | AB19: =AND(Z19,NOT(AA18),D19,O19>0) -> FALSE | AC19: =IF(AND(Y19,NOT(E19),O19+P19>0),O19/(O19+P19),1) -> 1 | AD19: =IF(AB19,O19,IF(D19,MIN(O19,IF(E19,AC19*X19+BF18,BE19*Inputs!$G$20)),0)) -> 3137336.5 | AE19: =IF(AB19,P19,IF(D19,MAX(MIN(P19,X19-MIN(O19,AC19*X19)),0),0)) -> 0 | AF19: =IF(OR(AB19,E19),0,MAX(H19-I19-K19-L19,0)) -> 89668728 | AG19: =IF(E19,0,O19-AD19) -> 82601663 | AH19: =IF(OR(AB19,E19),0,P19-AE19) -> 7064600.4 | AI19: =IF(D19,R19+AD19,0) -> 3687742.8 | AJ19: =(C19-Inputs!$G$6)/365 -> 2.1452055 | AK19: =AG19/Inputs!$C$10 -> 0.058427348 | AM19: =F19 -> 0.25555556 | AO19: =AO18+LN(1+($G19+AO$7)*$AM19) -> 0.054467689 | AP19: =AP18+LN(1+($G19+AP$7)*$AM19) -> 0.054683849 | AQ19: =AQ18+LN(1+($G19+AQ$7)*$AM19) -> 0.061627258 | AR19: =AR18+LN(1+($G19+AR$7)*$AM19) -> 0.061843243 | AS19: =AS18+LN(1+($G19+AS$7)*$AM19) -> 0.061705769 | AT19: =AT18+LN(1+($G19+AT$7)*$AM19) -> 0.061921752 | AU19: =AU18+LN(1+($G19+AU$7)*$AM19) -> 0.061705752 | AV19: =AV18+LN(1+($G19+AV$7)*$AM19) -> 0.061921735 | ... BD19: =BD18+LN(1+($G19+BD$7)*$AM19) -> 0.061921735 | BE19: =IF(AB19,O19,IF(D19,MIN(O19,AC19*X19+BF18),0)) -> 3137336.5 | BF19: =IF(OR(AB19,E19),0,BE19-AD19) -> 0 | BG19: =BG18+LN(1+($G19+BG$7)*$AM19) -> 0.059545631 | BI19: =BI18+LN(1+($G19+BI$7)*$AM19) -> 0.063865344 | BK19: =C19 -> 47072 | BL19: =AI19 -> 3687742.8
A20: 10 | B20: =EDATE(Inputs!$C$8,3*(A20-1)) -> 47164 | C20: =WORKDAY(B20-1,1) -> 47164 | D20: =C20<=Inputs!$C$9 -> TRUE | E20: =AND(D20,NOT(D21)) -> FALSE | F20: =(C20-C19)/360 -> 0.25555556 | G20: =Curve!D13 -> 0.02252 | H20: =AF19 -> 89668728 | I20: =IF(D20,H20*Inputs!$G$22,0) -> 22425.593 | J20: =MAX(Inputs!$G$24-(A20-1),1) -> 36.59177 | K20: =IF(D20,MIN(H20-I20,IF(J20>1,(H20-I20)*Inputs!$G$23/((1+Inputs!$G$23)^J20-1),H20-I20)),0) -> 2121059 | L20: =IF(D20,(H20-I20-K20)*Inputs!$G$21,0) -> 942894.92 | M20: =IF(A20>Inputs!$G$13,(1-Inputs!$G$12)*INDEX($I$11:$I$190,A20-Inputs!$G$13),0) -> 23185.088 | N20: =IF(D20,(H20-I20)*Inputs!$G$23,0) -> 711343.41 | O20: =AG19 -> 82601663 | P20: =AH19 -> 7064600.4 | Q20: =IF(AND(D20,O20+P20>0),Inputs!$C$25+Inputs!$C$26*H20/4,0) -> 122417.18 | R20: =O20*IF(Inputs!$G$19="",G20+Inputs!$C$13,MAX(Inputs!$G$19,G20+Inputs!$C$13))*F20 -> 530265.96 | S20: =P20*(G20+Inputs!$C$14)*F20 -> 53408.379 | T20: =N20+M20-Q20-R20-S20 -> 28436.973 | U20: =W19 -> 973.76764 | V20: =MIN(U20+I20,MAX(T20,0)) -> 23399.361 | W20: =U20+I20-V20 -> 0 | X20: =K20+L20+V20+IF(E20,H20-I20-K20-L20,0) -> 3087353.3 | Y20: =AND(Inputs!$C$21=1,O20/Inputs!$C$10<=Inputs!$C$22,Inputs!$G$14<Inputs!$C$23,W20<1) -> TRUE | Z20: =OR(AND(Inputs!$G$15=1,H20/Inputs!$C$17<=Inputs!$C$24),AND(Inputs!$G$15=2,C20>=Inputs!$G$16)) -> FALSE | AA20: =OR(AA19,Z20) -> FALSE | AB20: =AND(Z20,NOT(AA19),D20,O20>0) -> FALSE | AC20: =IF(AND(Y20,NOT(E20),O20+P20>0),O20/(O20+P20),1) -> 0.92121228 | AD20: =IF(AB20,O20,IF(D20,MIN(O20,IF(E20,AC20*X20+BF19,BE20*Inputs!$G$20)),0)) -> 2844107.7 | AE20: =IF(AB20,P20,IF(D20,MAX(MIN(P20,X20-MIN(O20,AC20*X20)),0),0)) -> 243245.52 | AF20: =IF(OR(AB20,E20),0,MAX(H20-I20-K20-L20,0)) -> 86582349 | AG20: =IF(E20,0,O20-AD20) -> 79757555 | AH20: =IF(OR(AB20,E20),0,P20-AE20) -> 6821354.9 | AI20: =IF(D20,R20+AD20,0) -> 3374373.7 | AJ20: =(C20-Inputs!$G$6)/365 -> 2.3972603 | AK20: =AG20/Inputs!$C$10 -> 0.056415601 | AM20: =F20 -> 0.25555556 | AO20: =AO19+LN(1+($G20+AO$7)*$AM20) -> 0.060866727 | AP20: =AP19+LN(1+($G20+AP$7)*$AM20) -> 0.061108279 | AQ20: =AQ19+LN(1+($G20+AQ$7)*$AM20) -> 0.068867315 | AR20: =AR19+LN(1+($G20+AR$7)*$AM20) -> 0.069108671 | AS20: =AS19+LN(1+($G20+AS$7)*$AM20) -> 0.068955048 | AT20: =AT19+LN(1+($G20+AT$7)*$AM20) -> 0.069196401 | AU20: =AU19+LN(1+($G20+AU$7)*$AM20) -> 0.068955029 | AV20: =AV19+LN(1+($G20+AV$7)*$AM20) -> 0.069196383 | ... BD20: =BD19+LN(1+($G20+BD$7)*$AM20) -> 0.069196383 | BE20: =IF(AB20,O20,IF(D20,MIN(O20,AC20*X20+BF19),0)) -> 2844107.7 | BF20: =IF(OR(AB20,E20),0,BE20-AD20) -> 0 | BG20: =BG19+LN(1+($G20+BG$7)*$AM20) -> 0.066541167 | BI20: =BI19+LN(1+($G20+BI$7)*$AM20) -> 0.071368299 | BK20: =C20 -> 47164 | BL20: =AI20 -> 3374373.7
A21: 11 | B21: =EDATE(Inputs!$C$8,3*(A21-1)) -> 47253 | C21: =WORKDAY(B21-1,1) -> 47253 | D21: =C21<=Inputs!$C$9 -> TRUE | E21: =AND(D21,NOT(D22)) -> FALSE | F21: =(C21-C20)/360 -> 0.24722222 | G21: =Curve!D14 -> 0.02252 | H21: =AF20 -> 86582349 | I21: =IF(D21,H21*Inputs!$G$22,0) -> 21653.709 | J21: =MAX(Inputs!$G$24-(A21-1),1) -> 35.59177 | K21: =IF(D21,MIN(H21-I21,IF(J21>1,(H21-I21)*Inputs!$G$23/((1+Inputs!$G$23)^J21-1),H21-I21)),0) -> 2114329.5 | L21: =IF(D21,(H21-I21-K21)*Inputs!$G$21,0) -> 909726.68 | M21: =IF(A21>Inputs!$G$13,(1-Inputs!$G$12)*INDEX($I$11:$I$190,A21-Inputs!$G$13),0) -> 22498.975 | N21: =IF(D21,(H21-I21)*Inputs!$G$23,0) -> 686859.11 | O21: =AG20 -> 79757555 | P21: =AH20 -> 6821354.9 | Q21: =IF(AND(D21,O21+P21>0),Inputs!$C$25+Inputs!$C$26*H21/4,0) -> 121645.59 | R21: =O21*IF(Inputs!$G$19="",G21+Inputs!$C$13,MAX(Inputs!$G$19,G21+Inputs!$C$13))*F21 -> 495312.14 | S21: =P21*(G21+Inputs!$C$14)*F21 -> 49887.831 | T21: =N21+M21-Q21-R21-S21 -> 42512.529 | U21: =W20 -> 0 | V21: =MIN(U21+I21,MAX(T21,0)) -> 21653.709 | W21: =U21+I21-V21 -> 0 | X21: =K21+L21+V21+IF(E21,H21-I21-K21-L21,0) -> 3045709.9 | Y21: =AND(Inputs!$C$21=1,O21/Inputs!$C$10<=Inputs!$C$22,Inputs!$G$14<Inputs!$C$23,W21<1) -> TRUE | Z21: =OR(AND(Inputs!$G$15=1,H21/Inputs!$C$17<=Inputs!$C$24),AND(Inputs!$G$15=2,C21>=Inputs!$G$16)) -> FALSE | AA21: =OR(AA20,Z21) -> FALSE | AB21: =AND(Z21,NOT(AA20),D21,O21>0) -> FALSE | AC21: =IF(AND(Y21,NOT(E21),O21+P21>0),O21/(O21+P21),1) -> 0.92121228 | AD21: =IF(AB21,O21,IF(D21,MIN(O21,IF(E21,AC21*X21+BF20,BE21*Inputs!$G$20)),0)) -> 2805745.4 | AE21: =IF(AB21,P21,IF(D21,MAX(MIN(P21,X21-MIN(O21,AC21*X21)),0),0)) -> 239964.54 | AF21: =IF(OR(AB21,E21),0,MAX(H21-I21-K21-L21,0)) -> 83536639 | AG21: =IF(E21,0,O21-AD21) -> 76951810 | AH21: =IF(OR(AB21,E21),0,P21-AE21) -> 6581390.3 | AI21: =IF(D21,R21+AD21,0) -> 3301057.5 | AJ21: =(C21-Inputs!$G$6)/365 -> 2.6410959 | AK21: =AG21/Inputs!$C$10 -> 0.054430988 | AM21: =F21 -> 0.24722222 | AO21: =AO20+LN(1+($G21+AO$7)*$AM21) -> 0.067057745 | AP21: =AP20+LN(1+($G21+AP$7)*$AM21) -> 0.067323867 | AQ21: =AQ20+LN(1+($G21+AQ$7)*$AM21) -> 0.075872108 | AR21: =AR20+LN(1+($G21+AR$7)*$AM21) -> 0.076138013 | AS21: =AS20+LN(1+($G21+AS$7)*$AM21) -> 0.075968764 | AT21: =AT20+LN(1+($G21+AT$7)*$AM21) -> 0.076234667 | AU21: =AU20+LN(1+($G21+AU$7)*$AM21) -> 0.075968744 | AV21: =AV20+LN(1+($G21+AV$7)*$AM21) -> 0.076234647 | ... BD21: =BD20+LN(1+($G21+BD$7)*$AM21) -> 0.076234647 | BE21: =IF(AB21,O21,IF(D21,MIN(O21,AC21*X21+BF20),0)) -> 2805745.4 | BF21: =IF(OR(AB21,E21),0,BE21-AD21) -> 0 | BG21: =BG20+LN(1+($G21+BG$7)*$AM21) -> 0.073309357 | BI21: =BI20+LN(1+($G21+BI$7)*$AM21) -> 0.078627478 | BK21: =C21 -> 47253 | BL21: =AI21 -> 3301057.5
A22: 12 | B22: =EDATE(Inputs!$C$8,3*(A22-1)) -> 47345 | C22: =WORKDAY(B22-1,1) -> 47345 | D22: =C22<=Inputs!$C$9 -> TRUE | E22: =AND(D22,NOT(D23)) -> FALSE | F22: =(C22-C21)/360 -> 0.25555556 | G22: =Curve!D15 -> 0.02252 | H22: =AF21 -> 83536639 | I22: =IF(D22,H22*Inputs!$G$22,0) -> 20891.996 | J22: =MAX(Inputs!$G$24-(A22-1),1) -> 34.59177 | K22: =IF(D22,MIN(H22-I22,IF(J22>1,(H22-I22)*Inputs!$G$23/((1+Inputs!$G$23)^J22-1),H22-I22)),0) -> 2107621.4 | L22: =IF(D22,(H22-I22-K22)*Inputs!$G$21,0) -> 876996.22 | M22: =IF(A22>Inputs!$G$13,(1-Inputs!$G$12)*INDEX($I$11:$I$190,A22-Inputs!$G$13),0) -> 21821.789 | N22: =IF(D22,(H22-I22)*Inputs!$G$23,0) -> 662697.45 | O22: =AG21 -> 76951810 | P22: =AH21 -> 6581390.3 | Q22: =IF(AND(D22,O22+P22>0),Inputs!$C$25+Inputs!$C$26*H22/4,0) -> 120884.16 | R22: =O22*IF(Inputs!$G$19="",G22+Inputs!$C$13,MAX(Inputs!$G$19,G22+Inputs!$C$13))*F22 -> 493996.42 | S22: =P22*(G22+Inputs!$C$14)*F22 -> 49755.311 | T22: =N22+M22-Q22-R22-S22 -> 19883.35 | U22: =W21 -> 0 | V22: =MIN(U22+I22,MAX(T22,0)) -> 19883.35 | W22: =U22+I22-V22 -> 1008.646 | X22: =K22+L22+V22+IF(E22,H22-I22-K22-L22,0) -> 3004501 | Y22: =AND(Inputs!$C$21=1,O22/Inputs!$C$10<=Inputs!$C$22,Inputs!$G$14<Inputs!$C$23,W22<1) -> FALSE | Z22: =OR(AND(Inputs!$G$15=1,H22/Inputs!$C$17<=Inputs!$C$24),AND(Inputs!$G$15=2,C22>=Inputs!$G$16)) -> FALSE | AA22: =OR(AA21,Z22) -> FALSE | AB22: =AND(Z22,NOT(AA21),D22,O22>0) -> FALSE | AC22: =IF(AND(Y22,NOT(E22),O22+P22>0),O22/(O22+P22),1) -> 1 | AD22: =IF(AB22,O22,IF(D22,MIN(O22,IF(E22,AC22*X22+BF21,BE22*Inputs!$G$20)),0)) -> 3004501 | AE22: =IF(AB22,P22,IF(D22,MAX(MIN(P22,X22-MIN(O22,AC22*X22)),0),0)) -> 0 | AF22: =IF(OR(AB22,E22),0,MAX(H22-I22-K22-L22,0)) -> 80531129 | AG22: =IF(E22,0,O22-AD22) -> 73947309 | AH22: =IF(OR(AB22,E22),0,P22-AE22) -> 6581390.3 | AI22: =IF(D22,R22+AD22,0) -> 3498497.4 | AJ22: =(C22-Inputs!$G$6)/365 -> 2.8931507 | AK22: =AG22/Inputs!$C$10 -> 0.052305789 | AM22: =F22 -> 0.25555556 | AO22: =AO21+LN(1+($G22+AO$7)*$AM22) -> 0.073456783 | AP22: =AP21+LN(1+($G22+AP$7)*$AM22) -> 0.073748297 | AQ22: =AQ21+LN(1+($G22+AQ$7)*$AM22) -> 0.083112165 | AR22: =AR21+LN(1+($G22+AR$7)*$AM22) -> 0.083403441 | AS22: =AS21+LN(1+($G22+AS$7)*$AM22) -> 0.083218044 | AT22: =AT21+LN(1+($G22+AT$7)*$AM22) -> 0.083509317 | AU22: =AU21+LN(1+($G22+AU$7)*$AM22) -> 0.083218021 | AV22: =AV21+LN(1+($G22+AV$7)*$AM22) -> 0.083509294 | ... BD22: =BD21+LN(1+($G22+BD$7)*$AM22) -> 0.083509294 | BE22: =IF(AB22,O22,IF(D22,MIN(O22,AC22*X22+BF21),0)) -> 3004501 | BF22: =IF(OR(AB22,E22),0,BE22-AD22) -> 0 | BG22: =BG21+LN(1+($G22+BG$7)*$AM22) -> 0.080304892 | BI22: =BI21+LN(1+($G22+BI$7)*$AM22) -> 0.086130433 | BK22: =C22 -> 47345 | BL22: =AI22 -> 3498497.4
